[Wed Jun 18 13:11:58 2014] [error] [client 127.0.0.1] mod_wsgi (pid=8282): Exception occurred processing WSGI script '/var/www/placeless/dotafarm/wsgi.py'.
[Wed Jun 18 13:11:58 2014] [error] [client 127.0.0.1] Traceback (most recent call last):
[Wed Jun 18 13:11:58 2014] [error] [client 127.0.0.1]   File "/home/ubuntu/.virtualenvs/dotafarm/lib/python2.7/site-packages/django/core/handlers/wsgi.py", line 187, in __call__
[Wed Jun 18 13:11:58 2014] [error] [client 127.0.0.1]     self.load_middleware()
[Wed Jun 18 13:11:58 2014] [error] [client 127.0.0.1]   File "/home/ubuntu/.virtualenvs/dotafarm/lib/python2.7/site-packages/django/core/handlers/base.py", line 44, in load_middleware
[Wed Jun 18 13:11:58 2014] [error] [client 127.0.0.1]     for middleware_path in settings.MIDDLEWARE_CLASSES:
[Wed Jun 18 13:11:58 2014] [error] [client 127.0.0.1]   File "/home/ubuntu/.virtualenvs/dotafarm/lib/python2.7/site-packages/django/conf/__init__.py", line 54, in __getattr__
[Wed Jun 18 13:11:58 2014] [error] [client 127.0.0.1]     self._setup(name)
[Wed Jun 18 13:11:58 2014] [error] [client 127.0.0.1]   File "/home/ubuntu/.virtualenvs/dotafarm/lib/python2.7/site-packages/django/conf/__init__.py", line 49, in _setup
[Wed Jun 18 13:11:58 2014] [error] [client 127.0.0.1]     self._wrapped = Settings(settings_module)
[Wed Jun 18 13:11:58 2014] [error] [client 127.0.0.1]   File "/home/ubuntu/.virtualenvs/dotafarm/lib/python2.7/site-packages/django/conf/__init__.py", line 132, in __init__
[Wed Jun 18 13:11:58 2014] [error] [client 127.0.0.1]     % (self.SETTINGS_MODULE, e)
[Wed Jun 18 13:11:58 2014] [error] [client 127.0.0.1] ImportError: Could not import settings 'dotafarm.settings' (Is it on sys.path? Is there an import error in the settings file?): No module named dotafarm.settings
[Wed Jun 18 14:11:21 2014] [error] [client 127.0.0.1] mod_wsgi (pid=8446): Exception occurred processing WSGI script '/var/www/placeless/dotafarm/wsgi.py'.
[Wed Jun 18 14:11:21 2014] [error] [client 127.0.0.1] Traceback (most recent call last):
[Wed Jun 18 14:11:21 2014] [error] [client 127.0.0.1]   File "/home/ubuntu/.virtualenvs/dotafarm/lib/python2.7/site-packages/django/core/handlers/wsgi.py", line 187, in __call__
[Wed Jun 18 14:11:21 2014] [error] [client 127.0.0.1]     self.load_middleware()
[Wed Jun 18 14:11:21 2014] [error] [client 127.0.0.1]   File "/home/ubuntu/.virtualenvs/dotafarm/lib/python2.7/site-packages/django/core/handlers/base.py", line 44, in load_middleware
[Wed Jun 18 14:11:21 2014] [error] [client 127.0.0.1]     for middleware_path in settings.MIDDLEWARE_CLASSES:
[Wed Jun 18 14:11:21 2014] [error] [client 127.0.0.1]   File "/home/ubuntu/.virtualenvs/dotafarm/lib/python2.7/site-packages/django/conf/__init__.py", line 54, in __getattr__
[Wed Jun 18 14:11:21 2014] [error] [client 127.0.0.1]     self._setup(name)
[Wed Jun 18 14:11:21 2014] [error] [client 127.0.0.1]   File "/home/ubuntu/.virtualenvs/dotafarm/lib/python2.7/site-packages/django/conf/__init__.py", line 49, in _setup
[Wed Jun 18 14:11:21 2014] [error] [client 127.0.0.1]     self._wrapped = Settings(settings_module)
[Wed Jun 18 14:11:21 2014] [error] [client 127.0.0.1]   File "/home/ubuntu/.virtualenvs/dotafarm/lib/python2.7/site-packages/django/conf/__init__.py", line 132, in __init__
[Wed Jun 18 14:11:21 2014] [error] [client 127.0.0.1]     % (self.SETTINGS_MODULE, e)
[Wed Jun 18 14:11:21 2014] [error] [client 127.0.0.1] ImportError: Could not import settings 'dotafarm.settings' (Is it on sys.path? Is there an import error in the settings file?): No module named dotafarm.settings
[Wed Jun 18 14:12:10 2014] [error] ['/home/ubuntu/.virtualenvs/dotafarm/lib/python2.7/site-packages/setuptools-0.6c11-py2.7.egg', '/home/ubuntu/.virtualenvs/dotafarm/lib/python2.7/site-packages/pip-1.1-py2.7.egg', '/var/www/placeless/dotafarm', '/home/ubuntu/.virtualenvs/dotafarm/lib/python2.7/site-packages', '/usr/local/lib/python2.7/dist-packages/openerp-6.2alpha-py2.7.egg', '/usr/lib/pymodules/python2.7', '/usr/local/lib/python2.7/dist-packages/openerp_web-6.1.1-py2.7.egg', '/usr/local/lib/python2.7/dist-packages/Werkzeug-0.7-py2.7.egg', '/usr/lib/python2.7', '/usr/lib/python2.7/plat-linux2', '/usr/lib/python2.7/lib-tk', '/usr/lib/python2.7/lib-old', '/usr/lib/python2.7/lib-dynload', '/usr/local/lib/python2.7/dist-packages', '/usr/lib/python2.7/dist-packages', '/usr/lib/python2.7/dist-packages/PIL', '/usr/lib/python2.7/dist-packages/gtk-2.0', '/var/www/placeless/dotafarm']
[Wed Jun 18 14:12:10 2014] [error] [client 127.0.0.1] mod_wsgi (pid=8496): Exception occurred processing WSGI script '/var/www/placeless/dotafarm/wsgi.py'.
[Wed Jun 18 14:12:10 2014] [error] [client 127.0.0.1] Traceback (most recent call last):
[Wed Jun 18 14:12:10 2014] [error] [client 127.0.0.1]   File "/home/ubuntu/.virtualenvs/dotafarm/lib/python2.7/site-packages/django/core/handlers/wsgi.py", line 187, in __call__
[Wed Jun 18 14:12:10 2014] [error] [client 127.0.0.1]     self.load_middleware()
[Wed Jun 18 14:12:10 2014] [error] [client 127.0.0.1]   File "/home/ubuntu/.virtualenvs/dotafarm/lib/python2.7/site-packages/django/core/handlers/base.py", line 44, in load_middleware
[Wed Jun 18 14:12:10 2014] [error] [client 127.0.0.1]     for middleware_path in settings.MIDDLEWARE_CLASSES:
[Wed Jun 18 14:12:10 2014] [error] [client 127.0.0.1]   File "/home/ubuntu/.virtualenvs/dotafarm/lib/python2.7/site-packages/django/conf/__init__.py", line 54, in __getattr__
[Wed Jun 18 14:12:10 2014] [error] [client 127.0.0.1]     self._setup(name)
[Wed Jun 18 14:12:10 2014] [error] [client 127.0.0.1]   File "/home/ubuntu/.virtualenvs/dotafarm/lib/python2.7/site-packages/django/conf/__init__.py", line 49, in _setup
[Wed Jun 18 14:12:10 2014] [error] [client 127.0.0.1]     self._wrapped = Settings(settings_module)
[Wed Jun 18 14:12:10 2014] [error] [client 127.0.0.1]   File "/home/ubuntu/.virtualenvs/dotafarm/lib/python2.7/site-packages/django/conf/__init__.py", line 132, in __init__
[Wed Jun 18 14:12:10 2014] [error] [client 127.0.0.1]     % (self.SETTINGS_MODULE, e)
[Wed Jun 18 14:12:10 2014] [error] [client 127.0.0.1] ImportError: Could not import settings 'dotafarm.settings' (Is it on sys.path? Is there an import error in the settings file?): No module named dotafarm.settings
[Wed Jun 18 14:12:33 2014] [error] [client 127.0.0.1] mod_wsgi (pid=8496): Exception occurred processing WSGI script '/var/www/placeless/dotafarm/wsgi.py'.
[Wed Jun 18 14:12:33 2014] [error] [client 127.0.0.1] Traceback (most recent call last):
[Wed Jun 18 14:12:33 2014] [error] [client 127.0.0.1]   File "/home/ubuntu/.virtualenvs/dotafarm/lib/python2.7/site-packages/django/core/handlers/wsgi.py", line 187, in __call__
[Wed Jun 18 14:12:33 2014] [error] [client 127.0.0.1]     self.load_middleware()
[Wed Jun 18 14:12:33 2014] [error] [client 127.0.0.1]   File "/home/ubuntu/.virtualenvs/dotafarm/lib/python2.7/site-packages/django/core/handlers/base.py", line 44, in load_middleware
[Wed Jun 18 14:12:33 2014] [error] [client 127.0.0.1]     for middleware_path in settings.MIDDLEWARE_CLASSES:
[Wed Jun 18 14:12:33 2014] [error] [client 127.0.0.1]   File "/home/ubuntu/.virtualenvs/dotafarm/lib/python2.7/site-packages/django/conf/__init__.py", line 54, in __getattr__
[Wed Jun 18 14:12:33 2014] [error] [client 127.0.0.1]     self._setup(name)
[Wed Jun 18 14:12:33 2014] [error] [client 127.0.0.1]   File "/home/ubuntu/.virtualenvs/dotafarm/lib/python2.7/site-packages/django/conf/__init__.py", line 49, in _setup
[Wed Jun 18 14:12:33 2014] [error] [client 127.0.0.1]     self._wrapped = Settings(settings_module)
[Wed Jun 18 14:12:33 2014] [error] [client 127.0.0.1]   File "/home/ubuntu/.virtualenvs/dotafarm/lib/python2.7/site-packages/django/conf/__init__.py", line 132, in __init__
[Wed Jun 18 14:12:33 2014] [error] [client 127.0.0.1]     % (self.SETTINGS_MODULE, e)
[Wed Jun 18 14:12:33 2014] [error] [client 127.0.0.1] ImportError: Could not import settings 'dotafarm.settings' (Is it on sys.path? Is there an import error in the settings file?): No module named dotafarm.settings
[Wed Jun 18 14:12:42 2014] [error] [client 127.0.0.1] mod_wsgi (pid=8496): Exception occurred processing WSGI script '/var/www/placeless/dotafarm/wsgi.py'.
[Wed Jun 18 14:12:42 2014] [error] [client 127.0.0.1] Traceback (most recent call last):
[Wed Jun 18 14:12:42 2014] [error] [client 127.0.0.1]   File "/home/ubuntu/.virtualenvs/dotafarm/lib/python2.7/site-packages/django/core/handlers/wsgi.py", line 187, in __call__
[Wed Jun 18 14:12:42 2014] [error] [client 127.0.0.1]     self.load_middleware()
[Wed Jun 18 14:12:42 2014] [error] [client 127.0.0.1]   File "/home/ubuntu/.virtualenvs/dotafarm/lib/python2.7/site-packages/django/core/handlers/base.py", line 44, in load_middleware
[Wed Jun 18 14:12:42 2014] [error] [client 127.0.0.1]     for middleware_path in settings.MIDDLEWARE_CLASSES:
[Wed Jun 18 14:12:42 2014] [error] [client 127.0.0.1]   File "/home/ubuntu/.virtualenvs/dotafarm/lib/python2.7/site-packages/django/conf/__init__.py", line 54, in __getattr__
[Wed Jun 18 14:12:42 2014] [error] [client 127.0.0.1]     self._setup(name)
[Wed Jun 18 14:12:42 2014] [error] [client 127.0.0.1]   File "/home/ubuntu/.virtualenvs/dotafarm/lib/python2.7/site-packages/django/conf/__init__.py", line 49, in _setup
[Wed Jun 18 14:12:42 2014] [error] [client 127.0.0.1]     self._wrapped = Settings(settings_module)
[Wed Jun 18 14:12:42 2014] [error] [client 127.0.0.1]   File "/home/ubuntu/.virtualenvs/dotafarm/lib/python2.7/site-packages/django/conf/__init__.py", line 132, in __init__
[Wed Jun 18 14:12:42 2014] [error] [client 127.0.0.1]     % (self.SETTINGS_MODULE, e)
[Wed Jun 18 14:12:42 2014] [error] [client 127.0.0.1] ImportError: Could not import settings 'dotafarm.settings' (Is it on sys.path? Is there an import error in the settings file?): No module named dotafarm.settings
[Wed Jun 18 14:13:10 2014] [error] [client 127.0.0.1] mod_wsgi (pid=8496): Exception occurred processing WSGI script '/var/www/placeless/dotafarm/wsgi.py'.
[Wed Jun 18 14:13:10 2014] [error] [client 127.0.0.1] Traceback (most recent call last):
[Wed Jun 18 14:13:10 2014] [error] [client 127.0.0.1]   File "/home/ubuntu/.virtualenvs/dotafarm/lib/python2.7/site-packages/django/core/handlers/wsgi.py", line 187, in __call__
[Wed Jun 18 14:13:10 2014] [error] [client 127.0.0.1]     self.load_middleware()
[Wed Jun 18 14:13:10 2014] [error] [client 127.0.0.1]   File "/home/ubuntu/.virtualenvs/dotafarm/lib/python2.7/site-packages/django/core/handlers/base.py", line 44, in load_middleware
[Wed Jun 18 14:13:10 2014] [error] [client 127.0.0.1]     for middleware_path in settings.MIDDLEWARE_CLASSES:
[Wed Jun 18 14:13:10 2014] [error] [client 127.0.0.1]   File "/home/ubuntu/.virtualenvs/dotafarm/lib/python2.7/site-packages/django/conf/__init__.py", line 54, in __getattr__
[Wed Jun 18 14:13:10 2014] [error] [client 127.0.0.1]     self._setup(name)
[Wed Jun 18 14:13:10 2014] [error] [client 127.0.0.1]   File "/home/ubuntu/.virtualenvs/dotafarm/lib/python2.7/site-packages/django/conf/__init__.py", line 49, in _setup
[Wed Jun 18 14:13:10 2014] [error] [client 127.0.0.1]     self._wrapped = Settings(settings_module)
[Wed Jun 18 14:13:10 2014] [error] [client 127.0.0.1]   File "/home/ubuntu/.virtualenvs/dotafarm/lib/python2.7/site-packages/django/conf/__init__.py", line 132, in __init__
[Wed Jun 18 14:13:10 2014] [error] [client 127.0.0.1]     % (self.SETTINGS_MODULE, e)
[Wed Jun 18 14:13:10 2014] [error] [client 127.0.0.1] ImportError: Could not import settings 'dotafarm.settings' (Is it on sys.path? Is there an import error in the settings file?): No module named dotafarm.settings
[Wed Jun 18 14:16:41 2014] [error] ['/home/ubuntu/.virtualenvs/dotafarm/lib/python2.7/site-packages/setuptools-0.6c11-py2.7.egg', '/home/ubuntu/.virtualenvs/dotafarm/lib/python2.7/site-packages/pip-1.1-py2.7.egg', '/var/www/placeless/dotafarm', '/home/ubuntu/.virtualenvs/dotafarm/lib/python2.7/site-packages', '/usr/local/lib/python2.7/dist-packages/openerp-6.2alpha-py2.7.egg', '/usr/lib/pymodules/python2.7', '/usr/local/lib/python2.7/dist-packages/openerp_web-6.1.1-py2.7.egg', '/usr/local/lib/python2.7/dist-packages/Werkzeug-0.7-py2.7.egg', '/usr/lib/python2.7', '/usr/lib/python2.7/plat-linux2', '/usr/lib/python2.7/lib-tk', '/usr/lib/python2.7/lib-old', '/usr/lib/python2.7/lib-dynload', '/usr/local/lib/python2.7/dist-packages', '/usr/lib/python2.7/dist-packages', '/usr/lib/python2.7/dist-packages/PIL', '/usr/lib/python2.7/dist-packages/gtk-2.0', '/var/www/placeless/dotafarm']
[Wed Jun 18 14:16:42 2014] [error] [client 127.0.0.1] mod_wsgi (pid=8825): Exception occurred processing WSGI script '/var/www/placeless/dotafarm/wsgi.py'.
[Wed Jun 18 14:16:42 2014] [error] [client 127.0.0.1] Traceback (most recent call last):
[Wed Jun 18 14:16:42 2014] [error] [client 127.0.0.1]   File "/home/ubuntu/.virtualenvs/dotafarm/lib/python2.7/site-packages/django/core/handlers/wsgi.py", line 187, in __call__
[Wed Jun 18 14:16:42 2014] [error] [client 127.0.0.1]     self.load_middleware()
[Wed Jun 18 14:16:42 2014] [error] [client 127.0.0.1]   File "/home/ubuntu/.virtualenvs/dotafarm/lib/python2.7/site-packages/django/core/handlers/base.py", line 44, in load_middleware
[Wed Jun 18 14:16:42 2014] [error] [client 127.0.0.1]     for middleware_path in settings.MIDDLEWARE_CLASSES:
[Wed Jun 18 14:16:42 2014] [error] [client 127.0.0.1]   File "/home/ubuntu/.virtualenvs/dotafarm/lib/python2.7/site-packages/django/conf/__init__.py", line 54, in __getattr__
[Wed Jun 18 14:16:42 2014] [error] [client 127.0.0.1]     self._setup(name)
[Wed Jun 18 14:16:42 2014] [error] [client 127.0.0.1]   File "/home/ubuntu/.virtualenvs/dotafarm/lib/python2.7/site-packages/django/conf/__init__.py", line 49, in _setup
[Wed Jun 18 14:16:42 2014] [error] [client 127.0.0.1]     self._wrapped = Settings(settings_module)
[Wed Jun 18 14:16:42 2014] [error] [client 127.0.0.1]   File "/home/ubuntu/.virtualenvs/dotafarm/lib/python2.7/site-packages/django/conf/__init__.py", line 132, in __init__
[Wed Jun 18 14:16:42 2014] [error] [client 127.0.0.1]     % (self.SETTINGS_MODULE, e)
[Wed Jun 18 14:16:42 2014] [error] [client 127.0.0.1] ImportError: Could not import settings 'dotafarm.settings' (Is it on sys.path? Is there an import error in the settings file?): No module named dotafarm.settings
[Wed Jun 18 14:23:42 2014] [error] [client 127.0.0.1] mod_wsgi (pid=9087): Exception occurred processing WSGI script '/var/www/placeless/dotafarm/wsgi.py'.
[Wed Jun 18 14:23:42 2014] [error] [client 127.0.0.1] Traceback (most recent call last):
[Wed Jun 18 14:23:42 2014] [error] [client 127.0.0.1]   File "/home/ubuntu/.virtualenvs/dotafarm/lib/python2.7/site-packages/django/core/handlers/wsgi.py", line 187, in __call__
[Wed Jun 18 14:23:42 2014] [error] [client 127.0.0.1]     self.load_middleware()
[Wed Jun 18 14:23:42 2014] [error] [client 127.0.0.1]   File "/home/ubuntu/.virtualenvs/dotafarm/lib/python2.7/site-packages/django/core/handlers/base.py", line 44, in load_middleware
[Wed Jun 18 14:23:42 2014] [error] [client 127.0.0.1]     for middleware_path in settings.MIDDLEWARE_CLASSES:
[Wed Jun 18 14:23:42 2014] [error] [client 127.0.0.1]   File "/home/ubuntu/.virtualenvs/dotafarm/lib/python2.7/site-packages/django/conf/__init__.py", line 54, in __getattr__
[Wed Jun 18 14:23:42 2014] [error] [client 127.0.0.1]     self._setup(name)
[Wed Jun 18 14:23:42 2014] [error] [client 127.0.0.1]   File "/home/ubuntu/.virtualenvs/dotafarm/lib/python2.7/site-packages/django/conf/__init__.py", line 49, in _setup
[Wed Jun 18 14:23:42 2014] [error] [client 127.0.0.1]     self._wrapped = Settings(settings_module)
[Wed Jun 18 14:23:42 2014] [error] [client 127.0.0.1]   File "/home/ubuntu/.virtualenvs/dotafarm/lib/python2.7/site-packages/django/conf/__init__.py", line 132, in __init__
[Wed Jun 18 14:23:42 2014] [error] [client 127.0.0.1]     % (self.SETTINGS_MODULE, e)
[Wed Jun 18 14:23:42 2014] [error] [client 127.0.0.1] ImportError: Could not import settings 'dotafarm.settings' (Is it on sys.path? Is there an import error in the settings file?): No module named dotafarm.settings
[Wed Jun 18 14:29:09 2014] [error] [client 127.0.0.1] mod_wsgi (pid=9148): Exception occurred processing WSGI script '/var/www/placeless/dotafarm/wsgi.py'.
[Wed Jun 18 14:29:09 2014] [error] [client 127.0.0.1] Traceback (most recent call last):
[Wed Jun 18 14:29:09 2014] [error] [client 127.0.0.1]   File "/home/ubuntu/.virtualenvs/dotafarm/lib/python2.7/site-packages/django/core/handlers/wsgi.py", line 187, in __call__
[Wed Jun 18 14:29:09 2014] [error] [client 127.0.0.1]     self.load_middleware()
[Wed Jun 18 14:29:09 2014] [error] [client 127.0.0.1]   File "/home/ubuntu/.virtualenvs/dotafarm/lib/python2.7/site-packages/django/core/handlers/base.py", line 44, in load_middleware
[Wed Jun 18 14:29:09 2014] [error] [client 127.0.0.1]     for middleware_path in settings.MIDDLEWARE_CLASSES:
[Wed Jun 18 14:29:09 2014] [error] [client 127.0.0.1]   File "/home/ubuntu/.virtualenvs/dotafarm/lib/python2.7/site-packages/django/conf/__init__.py", line 54, in __getattr__
[Wed Jun 18 14:29:09 2014] [error] [client 127.0.0.1]     self._setup(name)
[Wed Jun 18 14:29:09 2014] [error] [client 127.0.0.1]   File "/home/ubuntu/.virtualenvs/dotafarm/lib/python2.7/site-packages/django/conf/__init__.py", line 49, in _setup
[Wed Jun 18 14:29:09 2014] [error] [client 127.0.0.1]     self._wrapped = Settings(settings_module)
[Wed Jun 18 14:29:09 2014] [error] [client 127.0.0.1]   File "/home/ubuntu/.virtualenvs/dotafarm/lib/python2.7/site-packages/django/conf/__init__.py", line 132, in __init__
[Wed Jun 18 14:29:09 2014] [error] [client 127.0.0.1]     % (self.SETTINGS_MODULE, e)
[Wed Jun 18 14:29:09 2014] [error] [client 127.0.0.1] ImportError: Could not import settings 'dotafarm.settings' (Is it on sys.path? Is there an import error in the settings file?): No module named dotafarm.settings
[Wed Jun 18 18:50:05 2014] [error] /home/ubuntu/.virtualenvs/dotafarm/lib/python2.7/site-packages/mezzanine/utils/conf.py:51: UserWarning: You haven't defined the ALLOWED_HOSTS settings, which Django 1.5 requires. Will fall back to the domains configured as sites.
[Wed Jun 18 18:50:05 2014] [error]   warn("You haven't defined the ALLOWED_HOSTS settings, which "
[Wed Jun 18 18:50:05 2014] [error] [client 127.0.0.1] mod_wsgi (pid=9348): Exception occurred processing WSGI script '/var/www/placeless/dotafarm/wsgi.py'.
[Wed Jun 18 18:50:05 2014] [error] [client 127.0.0.1] Traceback (most recent call last):
[Wed Jun 18 18:50:05 2014] [error] [client 127.0.0.1]   File "/home/ubuntu/.virtualenvs/dotafarm/lib/python2.7/site-packages/django/core/handlers/wsgi.py", line 187, in __call__
[Wed Jun 18 18:50:05 2014] [error] [client 127.0.0.1]     self.load_middleware()
[Wed Jun 18 18:50:05 2014] [error] [client 127.0.0.1]   File "/home/ubuntu/.virtualenvs/dotafarm/lib/python2.7/site-packages/django/core/handlers/base.py", line 47, in load_middleware
[Wed Jun 18 18:50:05 2014] [error] [client 127.0.0.1]     mw_instance = mw_class()
[Wed Jun 18 18:50:05 2014] [error] [client 127.0.0.1]   File "/home/ubuntu/.virtualenvs/dotafarm/lib/python2.7/site-packages/django/middleware/locale.py", line 24, in __init__
[Wed Jun 18 18:50:05 2014] [error] [client 127.0.0.1]     for url_pattern in get_resolver(None).url_patterns:
[Wed Jun 18 18:50:05 2014] [error] [client 127.0.0.1]   File "/home/ubuntu/.virtualenvs/dotafarm/lib/python2.7/site-packages/django/core/urlresolvers.py", line 365, in url_patterns
[Wed Jun 18 18:50:05 2014] [error] [client 127.0.0.1]     patterns = getattr(self.urlconf_module, "urlpatterns", self.urlconf_module)
[Wed Jun 18 18:50:05 2014] [error] [client 127.0.0.1]   File "/home/ubuntu/.virtualenvs/dotafarm/lib/python2.7/site-packages/django/core/urlresolvers.py", line 360, in urlconf_module
[Wed Jun 18 18:50:05 2014] [error] [client 127.0.0.1]     self._urlconf_module = import_module(self.urlconf_name)
[Wed Jun 18 18:50:05 2014] [error] [client 127.0.0.1]   File "/home/ubuntu/.virtualenvs/dotafarm/lib/python2.7/site-packages/django/utils/importlib.py", line 40, in import_module
[Wed Jun 18 18:50:05 2014] [error] [client 127.0.0.1]     __import__(name)
[Wed Jun 18 18:50:05 2014] [error] [client 127.0.0.1] ImportError: No module named dotafarm.urls
[Wed Jun 18 18:50:45 2014] [error] [client 127.0.0.1] mod_wsgi (pid=9348): Exception occurred processing WSGI script '/var/www/placeless/dotafarm/wsgi.py'.
[Wed Jun 18 18:50:45 2014] [error] [client 127.0.0.1] Traceback (most recent call last):
[Wed Jun 18 18:50:45 2014] [error] [client 127.0.0.1]   File "/home/ubuntu/.virtualenvs/dotafarm/lib/python2.7/site-packages/django/core/handlers/wsgi.py", line 187, in __call__
[Wed Jun 18 18:50:45 2014] [error] [client 127.0.0.1]     self.load_middleware()
[Wed Jun 18 18:50:45 2014] [error] [client 127.0.0.1]   File "/home/ubuntu/.virtualenvs/dotafarm/lib/python2.7/site-packages/django/core/handlers/base.py", line 47, in load_middleware
[Wed Jun 18 18:50:45 2014] [error] [client 127.0.0.1]     mw_instance = mw_class()
[Wed Jun 18 18:50:45 2014] [error] [client 127.0.0.1]   File "/home/ubuntu/.virtualenvs/dotafarm/lib/python2.7/site-packages/django/middleware/locale.py", line 24, in __init__
[Wed Jun 18 18:50:45 2014] [error] [client 127.0.0.1]     for url_pattern in get_resolver(None).url_patterns:
[Wed Jun 18 18:50:45 2014] [error] [client 127.0.0.1]   File "/home/ubuntu/.virtualenvs/dotafarm/lib/python2.7/site-packages/django/core/urlresolvers.py", line 365, in url_patterns
[Wed Jun 18 18:50:45 2014] [error] [client 127.0.0.1]     patterns = getattr(self.urlconf_module, "urlpatterns", self.urlconf_module)
[Wed Jun 18 18:50:45 2014] [error] [client 127.0.0.1]   File "/home/ubuntu/.virtualenvs/dotafarm/lib/python2.7/site-packages/django/core/urlresolvers.py", line 360, in urlconf_module
[Wed Jun 18 18:50:45 2014] [error] [client 127.0.0.1]     self._urlconf_module = import_module(self.urlconf_name)
[Wed Jun 18 18:50:45 2014] [error] [client 127.0.0.1]   File "/home/ubuntu/.virtualenvs/dotafarm/lib/python2.7/site-packages/django/utils/importlib.py", line 40, in import_module
[Wed Jun 18 18:50:45 2014] [error] [client 127.0.0.1]     __import__(name)
[Wed Jun 18 18:50:45 2014] [error] [client 127.0.0.1] ImportError: No module named dotafarm.urls
[Wed Jun 18 18:52:38 2014] [error] /home/ubuntu/.virtualenvs/dotafarm/lib/python2.7/site-packages/mezzanine/utils/conf.py:51: UserWarning: You haven't defined the ALLOWED_HOSTS settings, which Django 1.5 requires. Will fall back to the domains configured as sites.
[Wed Jun 18 18:52:38 2014] [error]   warn("You haven't defined the ALLOWED_HOSTS settings, which "
[Wed Jun 18 18:52:38 2014] [error] [client 127.0.0.1] mod_wsgi (pid=9424): Exception occurred processing WSGI script '/var/www/placeless/dotafarm/wsgi.py'.
[Wed Jun 18 18:52:38 2014] [error] [client 127.0.0.1] Traceback (most recent call last):
[Wed Jun 18 18:52:38 2014] [error] [client 127.0.0.1]   File "/home/ubuntu/.virtualenvs/dotafarm/lib/python2.7/site-packages/django/core/handlers/wsgi.py", line 187, in __call__
[Wed Jun 18 18:52:38 2014] [error] [client 127.0.0.1]     self.load_middleware()
[Wed Jun 18 18:52:38 2014] [error] [client 127.0.0.1]   File "/home/ubuntu/.virtualenvs/dotafarm/lib/python2.7/site-packages/django/core/handlers/base.py", line 44, in load_middleware
[Wed Jun 18 18:52:38 2014] [error] [client 127.0.0.1]     for middleware_path in settings.MIDDLEWARE_CLASSES:
[Wed Jun 18 18:52:38 2014] [error] [client 127.0.0.1]   File "/home/ubuntu/.virtualenvs/dotafarm/lib/python2.7/site-packages/django/conf/__init__.py", line 54, in __getattr__
[Wed Jun 18 18:52:38 2014] [error] [client 127.0.0.1]     self._setup(name)
[Wed Jun 18 18:52:38 2014] [error] [client 127.0.0.1]   File "/home/ubuntu/.virtualenvs/dotafarm/lib/python2.7/site-packages/django/conf/__init__.py", line 49, in _setup
[Wed Jun 18 18:52:38 2014] [error] [client 127.0.0.1]     self._wrapped = Settings(settings_module)
[Wed Jun 18 18:52:38 2014] [error] [client 127.0.0.1]   File "/home/ubuntu/.virtualenvs/dotafarm/lib/python2.7/site-packages/django/conf/__init__.py", line 151, in __init__
[Wed Jun 18 18:52:38 2014] [error] [client 127.0.0.1]     raise ImproperlyConfigured("The SECRET_KEY setting must not be empty.")
[Wed Jun 18 18:52:38 2014] [error] [client 127.0.0.1] ImproperlyConfigured: The SECRET_KEY setting must not be empty.
[Wed Jun 18 18:53:19 2014] [error] /home/ubuntu/.virtualenvs/dotafarm/lib/python2.7/site-packages/mezzanine/utils/conf.py:51: UserWarning: You haven't defined the ALLOWED_HOSTS settings, which Django 1.5 requires. Will fall back to the domains configured as sites.
[Wed Jun 18 18:53:19 2014] [error]   warn("You haven't defined the ALLOWED_HOSTS settings, which "
[Wed Jun 18 18:53:19 2014] [error] [client 127.0.0.1] mod_wsgi (pid=9486): Exception occurred processing WSGI script '/var/www/placeless/dotafarm/wsgi.py'.
[Wed Jun 18 18:53:19 2014] [error] [client 127.0.0.1] Traceback (most recent call last):
[Wed Jun 18 18:53:19 2014] [error] [client 127.0.0.1]   File "/home/ubuntu/.virtualenvs/dotafarm/lib/python2.7/site-packages/django/core/handlers/wsgi.py", line 187, in __call__
[Wed Jun 18 18:53:19 2014] [error] [client 127.0.0.1]     self.load_middleware()
[Wed Jun 18 18:53:19 2014] [error] [client 127.0.0.1]   File "/home/ubuntu/.virtualenvs/dotafarm/lib/python2.7/site-packages/django/core/handlers/base.py", line 44, in load_middleware
[Wed Jun 18 18:53:19 2014] [error] [client 127.0.0.1]     for middleware_path in settings.MIDDLEWARE_CLASSES:
[Wed Jun 18 18:53:19 2014] [error] [client 127.0.0.1]   File "/home/ubuntu/.virtualenvs/dotafarm/lib/python2.7/site-packages/django/conf/__init__.py", line 54, in __getattr__
[Wed Jun 18 18:53:19 2014] [error] [client 127.0.0.1]     self._setup(name)
[Wed Jun 18 18:53:19 2014] [error] [client 127.0.0.1]   File "/home/ubuntu/.virtualenvs/dotafarm/lib/python2.7/site-packages/django/conf/__init__.py", line 49, in _setup
[Wed Jun 18 18:53:19 2014] [error] [client 127.0.0.1]     self._wrapped = Settings(settings_module)
[Wed Jun 18 18:53:19 2014] [error] [client 127.0.0.1]   File "/home/ubuntu/.virtualenvs/dotafarm/lib/python2.7/site-packages/django/conf/__init__.py", line 151, in __init__
[Wed Jun 18 18:53:19 2014] [error] [client 127.0.0.1]     raise ImproperlyConfigured("The SECRET_KEY setting must not be empty.")
[Wed Jun 18 18:53:19 2014] [error] [client 127.0.0.1] ImproperlyConfigured: The SECRET_KEY setting must not be empty.
[Wed Jun 18 18:54:08 2014] [error] [client 127.0.0.1] mod_wsgi (pid=9548): Exception occurred processing WSGI script '/var/www/placeless/dotafarm/wsgi.py'.
[Wed Jun 18 18:54:08 2014] [error] [client 127.0.0.1] Traceback (most recent call last):
[Wed Jun 18 18:54:08 2014] [error] [client 127.0.0.1]   File "/home/ubuntu/.virtualenvs/dotafarm/lib/python2.7/site-packages/django/core/handlers/wsgi.py", line 187, in __call__
[Wed Jun 18 18:54:08 2014] [error] [client 127.0.0.1]     self.load_middleware()
[Wed Jun 18 18:54:08 2014] [error] [client 127.0.0.1]   File "/home/ubuntu/.virtualenvs/dotafarm/lib/python2.7/site-packages/django/core/handlers/base.py", line 44, in load_middleware
[Wed Jun 18 18:54:08 2014] [error] [client 127.0.0.1]     for middleware_path in settings.MIDDLEWARE_CLASSES:
[Wed Jun 18 18:54:08 2014] [error] [client 127.0.0.1]   File "/home/ubuntu/.virtualenvs/dotafarm/lib/python2.7/site-packages/django/conf/__init__.py", line 54, in __getattr__
[Wed Jun 18 18:54:08 2014] [error] [client 127.0.0.1]     self._setup(name)
[Wed Jun 18 18:54:08 2014] [error] [client 127.0.0.1]   File "/home/ubuntu/.virtualenvs/dotafarm/lib/python2.7/site-packages/django/conf/__init__.py", line 49, in _setup
[Wed Jun 18 18:54:08 2014] [error] [client 127.0.0.1]     self._wrapped = Settings(settings_module)
[Wed Jun 18 18:54:08 2014] [error] [client 127.0.0.1]   File "/home/ubuntu/.virtualenvs/dotafarm/lib/python2.7/site-packages/django/conf/__init__.py", line 132, in __init__
[Wed Jun 18 18:54:08 2014] [error] [client 127.0.0.1]     % (self.SETTINGS_MODULE, e)
[Wed Jun 18 18:54:08 2014] [error] [client 127.0.0.1] ImportError: Could not import settings 'dotafarm.settings' (Is it on sys.path? Is there an import error in the settings file?): No module named dotafarm.settings
[Wed Jun 18 19:02:56 2014] [error] [client 127.0.0.1] mod_wsgi (pid=9682): Target WSGI script '/var/www/placeless/dotafarm/wsgi.py' cannot be loaded as Python module.
[Wed Jun 18 19:02:56 2014] [error] [client 127.0.0.1] mod_wsgi (pid=9682): Exception occurred processing WSGI script '/var/www/placeless/dotafarm/wsgi.py'.
[Wed Jun 18 19:02:56 2014] [error] [client 127.0.0.1] Traceback (most recent call last):
[Wed Jun 18 19:02:56 2014] [error] [client 127.0.0.1]   File "/var/www/placeless/dotafarm/wsgi.py", line 7, in <module>
[Wed Jun 18 19:02:56 2014] [error] [client 127.0.0.1]     sys.append('/var/www/placeless/dotafarm')
[Wed Jun 18 19:02:56 2014] [error] [client 127.0.0.1] AttributeError: 'module' object has no attribute 'append'
[Wed Jun 18 19:03:39 2014] [error] /home/ubuntu/.virtualenvs/dotafarm/lib/python2.7/site-packages/mezzanine/utils/conf.py:51: UserWarning: You haven't defined the ALLOWED_HOSTS settings, which Django 1.5 requires. Will fall back to the domains configured as sites.
[Wed Jun 18 19:03:39 2014] [error]   warn("You haven't defined the ALLOWED_HOSTS settings, which "
[Wed Jun 18 19:03:39 2014] [error] [client 127.0.0.1] mod_wsgi (pid=9743): Exception occurred processing WSGI script '/var/www/placeless/dotafarm/wsgi.py'.
[Wed Jun 18 19:03:39 2014] [error] [client 127.0.0.1] Traceback (most recent call last):
[Wed Jun 18 19:03:39 2014] [error] [client 127.0.0.1]   File "/home/ubuntu/.virtualenvs/dotafarm/lib/python2.7/site-packages/django/core/handlers/wsgi.py", line 187, in __call__
[Wed Jun 18 19:03:39 2014] [error] [client 127.0.0.1]     self.load_middleware()
[Wed Jun 18 19:03:39 2014] [error] [client 127.0.0.1]   File "/home/ubuntu/.virtualenvs/dotafarm/lib/python2.7/site-packages/django/core/handlers/base.py", line 47, in load_middleware
[Wed Jun 18 19:03:39 2014] [error] [client 127.0.0.1]     mw_instance = mw_class()
[Wed Jun 18 19:03:39 2014] [error] [client 127.0.0.1]   File "/home/ubuntu/.virtualenvs/dotafarm/lib/python2.7/site-packages/django/middleware/locale.py", line 24, in __init__
[Wed Jun 18 19:03:39 2014] [error] [client 127.0.0.1]     for url_pattern in get_resolver(None).url_patterns:
[Wed Jun 18 19:03:39 2014] [error] [client 127.0.0.1]   File "/home/ubuntu/.virtualenvs/dotafarm/lib/python2.7/site-packages/django/core/urlresolvers.py", line 365, in url_patterns
[Wed Jun 18 19:03:39 2014] [error] [client 127.0.0.1]     patterns = getattr(self.urlconf_module, "urlpatterns", self.urlconf_module)
[Wed Jun 18 19:03:39 2014] [error] [client 127.0.0.1]   File "/home/ubuntu/.virtualenvs/dotafarm/lib/python2.7/site-packages/django/core/urlresolvers.py", line 360, in urlconf_module
[Wed Jun 18 19:03:39 2014] [error] [client 127.0.0.1]     self._urlconf_module = import_module(self.urlconf_name)
[Wed Jun 18 19:03:39 2014] [error] [client 127.0.0.1]   File "/home/ubuntu/.virtualenvs/dotafarm/lib/python2.7/site-packages/django/utils/importlib.py", line 40, in import_module
[Wed Jun 18 19:03:39 2014] [error] [client 127.0.0.1]     __import__(name)
[Wed Jun 18 19:03:39 2014] [error] [client 127.0.0.1] ImportError: No module named dotafarm.urls
[Wed Jun 18 19:20:25 2014] [error] /home/ubuntu/.virtualenvs/dotafarm/lib/python2.7/site-packages/mezzanine/utils/conf.py:51: UserWarning: You haven't defined the ALLOWED_HOSTS settings, which Django 1.5 requires. Will fall back to the domains configured as sites.
[Wed Jun 18 19:20:25 2014] [error]   warn("You haven't defined the ALLOWED_HOSTS settings, which "
[Wed Jun 18 19:20:27 2014] [error] [client 127.0.0.1] mod_wsgi (pid=9823): Exception occurred processing WSGI script '/var/www/placeless/dotafarm/wsgi.py'.
[Wed Jun 18 19:20:27 2014] [error] [client 127.0.0.1] IOError: failed to write data
[Wed Jun 18 19:21:02 2014] [error] [client 127.0.0.1] mod_wsgi (pid=9823): Exception occurred processing WSGI script '/var/www/placeless/dotafarm/wsgi.py'.
[Wed Jun 18 19:21:02 2014] [error] [client 127.0.0.1] IOError: failed to write data
[Wed Jun 18 19:22:20 2014] [error] [client 127.0.0.1] mod_wsgi (pid=9823): Exception occurred processing WSGI script '/var/www/placeless/dotafarm/wsgi.py'.
[Wed Jun 18 19:22:20 2014] [error] [client 127.0.0.1] IOError: failed to write data
Fatal Python error: Couldn't create autoTLSkey mapping
Fatal Python error: Couldn't create autoTLSkey mapping
[Wed Jun 18 20:35:36 2014] [error] /home/ubuntu/.virtualenvs/dotafarm/lib/python2.7/site-packages/mezzanine/utils/conf.py:51: UserWarning: You haven't defined the ALLOWED_HOSTS settings, which Django 1.5 requires. Will fall back to the domains configured as sites.
[Wed Jun 18 20:35:36 2014] [error]   warn("You haven't defined the ALLOWED_HOSTS settings, which "
[Wed Jun 18 20:36:09 2014] [error] /home/ubuntu/.virtualenvs/dotafarm/lib/python2.7/site-packages/mezzanine/utils/conf.py:51: UserWarning: You haven't defined the ALLOWED_HOSTS settings, which Django 1.5 requires. Will fall back to the domains configured as sites.
[Wed Jun 18 20:36:09 2014] [error]   warn("You haven't defined the ALLOWED_HOSTS settings, which "
[Thu Jun 19 00:23:08 2014] [error] /home/ubuntu/.virtualenvs/dotafarm/lib/python2.7/site-packages/mezzanine/utils/conf.py:51: UserWarning: You haven't defined the ALLOWED_HOSTS settings, which Django 1.5 requires. Will fall back to the domains configured as sites.
[Thu Jun 19 00:23:08 2014] [error]   warn("You haven't defined the ALLOWED_HOSTS settings, which "
Fatal Python error: Couldn't create autoTLSkey mapping
[Thu Jun 19 00:25:49 2014] [error] /home/ubuntu/.virtualenvs/dotafarm/lib/python2.7/site-packages/mezzanine/utils/conf.py:51: UserWarning: You haven't defined the ALLOWED_HOSTS settings, which Django 1.5 requires. Will fall back to the domains configured as sites.
[Thu Jun 19 00:25:49 2014] [error]   warn("You haven't defined the ALLOWED_HOSTS settings, which "
Fatal Python error: Couldn't create autoTLSkey mapping
Fatal Python error: Couldn't create autoTLSkey mapping
Fatal Python error: Couldn't create autoTLSkey mapping
[Thu Jun 19 00:26:47 2014] [error] /home/ubuntu/.virtualenvs/dotafarm/lib/python2.7/site-packages/mezzanine/utils/conf.py:51: UserWarning: You haven't defined the ALLOWED_HOSTS settings, which Django 1.5 requires. Will fall back to the domains configured as sites.
[Thu Jun 19 00:26:47 2014] [error]   warn("You haven't defined the ALLOWED_HOSTS settings, which "
Fatal Python error: Couldn't create autoTLSkey mapping
Fatal Python error: Couldn't create autoTLSkey mapping
Fatal Python error: Couldn't create autoTLSkey mapping
Fatal Python error: Couldn't create autoTLSkey mapping
Fatal Python error: Couldn't create autoTLSkey mapping
Fatal Python error: Couldn't create autoTLSkey mapping
Fatal Python error: Couldn't create autoTLSkey mapping
Fatal Python error: Couldn't create autoTLSkey mapping
[Thu Jun 19 15:19:05 2014] [error] /home/ubuntu/.virtualenvs/dotafarm/lib/python2.7/site-packages/mezzanine/utils/conf.py:51: UserWarning: You haven't defined the ALLOWED_HOSTS settings, which Django 1.5 requires. Will fall back to the domains configured as sites.
[Thu Jun 19 15:19:05 2014] [error]   warn("You haven't defined the ALLOWED_HOSTS settings, which "
Fatal Python error: Couldn't create autoTLSkey mapping
[Thu Jun 19 15:23:45 2014] [error] /home/ubuntu/.virtualenvs/dotafarm/lib/python2.7/site-packages/mezzanine/utils/conf.py:51: UserWarning: You haven't defined the ALLOWED_HOSTS settings, which Django 1.5 requires. Will fall back to the domains configured as sites.
[Thu Jun 19 15:23:45 2014] [error]   warn("You haven't defined the ALLOWED_HOSTS settings, which "
[Thu Jun 19 15:26:45 2014] [error] /home/ubuntu/.virtualenvs/dotafarm/lib/python2.7/site-packages/mezzanine/utils/conf.py:51: UserWarning: You haven't defined the ALLOWED_HOSTS settings, which Django 1.5 requires. Will fall back to the domains configured as sites.
[Thu Jun 19 15:26:45 2014] [error]   warn("You haven't defined the ALLOWED_HOSTS settings, which "
Fatal Python error: Couldn't create autoTLSkey mapping
Fatal Python error: Couldn't create autoTLSkey mapping
Fatal Python error: Couldn't create autoTLSkey mapping
Fatal Python error: Couldn't create autoTLSkey mapping
